Workbook

Sheet README
A1: ASTON MARTIN LAGONDA - LIQUIDITY AND CAPITAL STRUCTURE MODEL
A3: Purpose | B3: Credit / capital-structure analysis of the July 2026 GBP 550m private-credit financing. NOT a valuation model.
A4: Question | B4: Did the financing solve the liquidity problem, or postpone further deleveraging / an equity raise?
A6: PHASE | B6: Phase 2 (model build) complete. Phase 3 (downside scenario) NOT built - parameters await sign-off.
A8: SOURCING RULE | B8: Every hard-coded figure traces to an AML primary document. See SOURCES.md.
B9: Press reporting (bondholder friction / drop-down) is NOT an input to this model anywhere.
A11: COLOUR CODE
A12: BLUE | B12: Sourced from an AML primary document.
A13: AMBER | B13: PROVISIONAL judgement - awaiting sign-off. Drives the conclusion. Edit on Assumptions tab.
A14: RED | B14: Unsourced / disclosed limitation.
A15: BLACK | B15: Calculated - do not overwrite.
A17: TABS
A18: Assumptions | B18: All inputs. The ONLY tab you should edit.
A19: Debt | B19: Pre vs post capital structure, interest schedule, reconciliation to reported net debt.
A20: Model | B20: P and L, free cash flow, net debt and liquidity roll-forward FY2025A to FY2031E.
A21: Outputs | B21: Credit metrics dashboard and the headline answer.
A22: Maturity | B22: Debt maturity profile.
A24: KEY FLAGS
A25: A1 Txn costs | B25: Not disclosed by AML. Band 30/40/50; central GBP 40m reproduces the disclosed c.GBP 340m.
A26: A2 DDTL | B26: GBP 100m delayed draw EXCLUDED from pro forma liquidity (CFO confirmed). Memo item only.
A27: Covenant | B27: SSTL minimum-liquidity covenant tested monthly from Aug-2026 but the LEVEL is not disclosed.
A28: FY27-31 | B28: AML gives NO quantified guidance beyond FY2026. All FY2027+ drivers are provisional.
A29: REFI RATE | B29: 20.16pct is a market-implied DISTRESS yield, NOT a forecast new-issue coupon. This caveat must travel
B30: with the number into the memo and deck - it is not sufficient for it to sit on the YTM tab alone.
A32: ATTRIBUTION | B32: See the Attribution tab: the leverage reversal is driven MAINLY by the margin cap, not the refi rate.

Sheet Assumptions
A1: ASSUMPTIONS - the only tab to edit
A3: SCENARIO SWITCH | B3: 1 | C3: =IF(B3=1,"BASE CASE","DOWNSIDE CASE") -> BASE CASE
A4: 1 = Base. 2 = Downside (single combined stress: volumes, gross margin and SONIA together from FY2027).
A6: LEGEND
A7: BLUE = sourced from AML primary document
A8: AMBER = PROVISIONAL, awaiting sign-off
A9: RED = unsourced / limitation
A11: ACTIVE DRIVERS - CALCULATED, switch with B3. Edit the BASE and DOWNSIDE blocks below.
A12: Driver | B12: FY2025A | C12: FY2026E | D12: FY2027E | E12: FY2028E | F12: FY2029E | G12: FY2030E | H12: FY2031E | I12: Basis
A13: Total wholesale volumes | B13: =IF($B$3=1,B42,B57) -> 5448 | C13: =IF($B$3=1,C42,C57) -> 5900 | D13: =IF($B$3=1,D42,D57) -> 6100 | E13: =IF($B$3=1,E42,E57) -> 6300 | F13: =IF($B$3=1,F42,F57) -> 6400 | G13: =IF($B$3=1,G42,G57) -> 6500 | H13: =IF($B$3=1,H42,H57) -> 6600 | I13: CALCULATED - base row 42 / downside row 57
A14: Blended ASP (GBP k) | B14: =IF($B$3=1,B43,B58) -> 230.9 | C14: =IF($B$3=1,C43,C58) -> 271 | D14: =IF($B$3=1,D43,D58) -> 274 | E14: =IF($B$3=1,E43,E58) -> 277 | F14: =IF($B$3=1,F43,F58) -> 280 | G14: =IF($B$3=1,G43,G58) -> 283 | H14: =IF($B$3=1,H43,H58) -> 286 | I14: CALCULATED - base row 43 / downside row 58
A15: Gross margin pct | B15: =IF($B$3=1,B44,B59) -> 0.294 | C15: =IF($B$3=1,C44,C59) -> 0.35 | D15: =IF($B$3=1,D44,D59) -> 0.355 | E15: =IF($B$3=1,E44,E59) -> 0.355 | F15: =IF($B$3=1,F44,F59) -> 0.355 | G15: =IF($B$3=1,G44,G59) -> 0.355 | H15: =IF($B$3=1,H44,H59) -> 0.355 | I15: CALCULATED - base row 44 / downside row 59
A16: Adjusted opex ex D and A | B16: =IF($B$3=1,B45,B60) -> 262 | C16: =IF($B$3=1,C45,C60) -> 295 | D16: =IF($B$3=1,D45,D60) -> 305 | E16: =IF($B$3=1,E45,E60) -> 320 | F16: =IF($B$3=1,F45,F60) -> 330 | G16: =IF($B$3=1,G45,G60) -> 340 | H16: =IF($B$3=1,H45,H60) -> 350 | I16: CALCULATED - base row 45 / downside row 60
A17: Adjusted D and A | B17: =IF($B$3=1,B46,B61) -> 297 | C17: =IF($B$3=1,C46,C61) -> 387.5 | D17: =IF($B$3=1,D46,D61) -> 390 | E17: =IF($B$3=1,E46,E61) -> 380 | F17: =IF($B$3=1,F46,F61) -> 370 | G17: =IF($B$3=1,G46,G61) -> 360 | H17: =IF($B$3=1,H46,H61) -> 350 | I17: CALCULATED - base row 46 / downside row 61
A18: Capex | B18: =IF($B$3=1,B47,B62) -> 341 | C18: =IF($B$3=1,C47,C62) -> 300 | D18: =IF($B$3=1,D47,D62) -> 350 | E18: =IF($B$3=1,E47,E62) -> 350 | F18: =IF($B$3=1,F47,F62) -> 350 | G18: =IF($B$3=1,G47,G62) -> 350 | H18: =IF($B$3=1,H47,H62) -> 300 | I18: CALCULATED - base row 47 / downside row 62
A19: Working capital movement | B19: =IF($B$3=1,B48,B63) -> 0 | C19: =IF($B$3=1,C48,C63) -> -20 | D19: =IF($B$3=1,D48,D63) -> -10 | E19: =IF($B$3=1,E48,E63) -> -10 | F19: =IF($B$3=1,F48,F63) -> -10 | G19: =IF($B$3=1,G48,G63) -> -10 | H19: =IF($B$3=1,H48,H63) -> -10 | I19: CALCULATED - base row 48 / downside row 63
A20: Lease payments | B20: =IF($B$3=1,B49,B64) -> 0 | C20: =IF($B$3=1,C49,C64) -> -10 | D20: =IF($B$3=1,D49,D64) -> -10 | E20: =IF($B$3=1,E49,E64) -> -10 | F20: =IF($B$3=1,F49,F64) -> -10 | G20: =IF($B$3=1,G49,G64) -> -10 | H20: =IF($B$3=1,H49,H64) -> -10 | I20: CALCULATED - base row 49 / downside row 64
A21: Cash tax | B21: =IF($B$3=1,B50,B65) -> 0 | C21: =IF($B$3=1,C50,C65) -> -5 | D21: =IF($B$3=1,D50,D65) -> -5 | E21: =IF($B$3=1,E50,E65) -> -5 | F21: =IF($B$3=1,F50,F65) -> -5 | G21: =IF($B$3=1,G50,G65) -> -5 | H21: =IF($B$3=1,H50,H65) -> -5 | I21: CALCULATED - base row 50 / downside row 65
A22: Other cash items | B22: =IF($B$3=1,B51,B66) -> 0 | C22: =IF($B$3=1,C51,C66) -> 0 | D22: =IF($B$3=1,D51,D66) -> 0 | E22: =IF($B$3=1,E51,E66) -> 0 | F22: =IF($B$3=1,F51,F66) -> 0 | G22: =IF($B$3=1,G51,G66) -> 0 | H22: =IF($B$3=1,H51,H66) -> 0 | I22: CALCULATED - base row 51 / downside row 66
A24: RATES AND FX
A25: Driver | B25: FY2025A | C25: FY2026E | D25: FY2027E | E25: FY2028E | F25: FY2029E | G25: FY2030E | H25: FY2031E | I25: Basis
A26: SONIA | B26: =IF($B$3=1,B52,B67) -> 0.0372 | C26: =IF($B$3=1,C52,C67) -> 0.0372 | D26: =IF($B$3=1,D52,D67) -> 0.0372 | E26: =IF($B$3=1,E52,E67) -> 0.0372 | F26: =IF($B$3=1,F52,F67) -> 0.0372 | G26: =IF($B$3=1,G52,G67) -> 0.0372 | H26: =IF($B$3=1,H52,H67) -> 0.0372 | I26: CALCULATED - base row 52 / downside row 67.
A27: USD per GBP | B27: 1.3253 | C27: 1.3253 | D27: 1.3253 | E27: 1.3253 | F27: 1.3253 | G27: 1.3253 | H27: 1.3253 | I27: SOURCED (derived): USD 1,050.0m / GBP 792.3m at 30-Jun-26 [H1].
A28: SSTL margin over SONIA | B28: 0.0675 | C28: 0.0675 | D28: 0.0675 | E28: 0.0675 | F28: 0.0675 | G28: 0.0675 | H28: 0.0675 | I28: SOURCED: SONIA + 6.75pct [H1].
A29: Refi rate on 2029 notes | B29: 0.2016 | C29: 0.2016 | D29: 0.2016 | E29: 0.2016 | F29: 0.2016 | G29: 0.2016 | H29: 0.2016 | I29: COMPUTED blended YTM from the 30-Jun-26 market price (79.57pct of par). CAVEAT: this is a market-implied DISTRESS yield embedding default probability, NOT a forecast new-issue coupon - never quote it without that caveat. See YTM tab.
A31: SWITCHES AND SINGLE INPUTS
A32: Transaction cost case (1=Low 2=Central 3=High) | B32: 2 | I32: User-approved band 30/40/50. Central reproduces the disclosed c.GBP 340m.
A33: Transaction costs (GBP m) | B33: =CHOOSE(B32,30,40,50) -> 40 | I33: A1 - NOT DISCLOSED by AML. Unverified pending FY2026 Annual Report.
A34: DDTL drawn (0=No 1=Yes) | B34: =IF($B$3=1,0,1) -> 0 | I34: CALCULATED - undrawn in base, DRAWN in downside (a company under liquidity stress draws committed capacity). A2: excluded from the disclosed c.GBP 340m (CFO confirmed).
A35: Refinance 2029 notes at maturity (0/1) | B35: 1 | I35: Set to 0 to expose the raw 2029 funding wall.
A36: Minimum liquidity covenant (GBP m) | B36: 100 | I36: QUANTUM NOT DISCLOSED. Covenant exists, tested monthly from Aug-26 [H1].
A37: Inventory financing assumed rolled (0/1) | B37: 1 | I37: GBP 39.1m repayable Oct-26 (GBP 40.0m gross) [H1]. Assumed rolled.
A40: BASE CASE INPUTS - edit here
A41: Driver | B41: FY2025A | C41: FY2026E | D41: FY2027E | E41: FY2028E | F41: FY2029E | G41: FY2030E | H41: FY2031E | I41: Basis
A42: Total wholesale volumes | B42: 5448 | C42: 5900 | D42: 6100 | E42: 6300 | F42: 6400 | G42: 6500 | H42: 6600 | I42: FY25A sourced [AR25]. FY26+ PROVISIONAL - no volume guidance is given.
A43: Blended ASP (GBP k) | B43: 230.9 | C43: 271 | D43: 274 | E43: 277 | F43: 280 | G43: 283 | H43: 286 | I43: FY25A = revenue/volume. FY26+ PROVISIONAL (c.500 Valhalla in FY26 is sourced).
A44: Gross margin pct | B44: 0.294 | C44: 0.35 | D44: 0.355 | E44: 0.355 | F44: 0.355 | G44: 0.355 | H44: 0.355 | I44: FY25A sourced. H1-26A 33.8pct sourced. FY26+ PROVISIONAL, set so EBITDA margin caps at c.17.1pct.
A45: Adjusted opex ex D and A | B45: 262 | C45: 295 | D45: 305 | E45: 320 | F45: 330 | G45: 340 | H45: 350 | I45: FY25A sourced. FY26 below 300 = GUIDANCE. FY27+ PROVISIONAL, calibrated to the 17.1pct margin cap.
A46: Adjusted D and A | B46: 297 | C46: 387.5 | D46: 390 | E46: 380 | F46: 370 | G46: 360 | H46: 350 | I46: FY25A sourced. FY26 375-400 = GUIDANCE (midpoint). FY27+ PROVISIONAL.
A47: Capex | B47: 341 | C47: 300 | D47: 350 | E47: 350 | F47: 350 | G47: 350 | H47: 300 | I47: FY25A sourced. FY26 c.300 = GUIDANCE. FY26-30 sums to c.GBP 1.7bn = GUIDANCE.
...

Sheet Debt
A1: CAPITAL STRUCTURE - PRE vs POST TRANSACTION (GBP m, nominal principal)
A3: Instrument | B3: Pre 30-Jun-26 | C3: Transaction | D3: Post pro forma | E3: Coupon | F3: Maturity | G3: Source
A4: USD SSN (USD 1,050.0m at 10.0pct) | B4: 792.3 | C4: 0 | D4: =B4+C4 -> 792.3 | E4: 10.0pct | F4: 47178 | G4: [H1] fair value note
A5: GBP SSN (GBP 465.0m at 10.375pct) | B5: 465 | C5: 0 | D5: =B5+C5 -> 465 | E5: 10.375pct | F5: 47178 | G5: [H1] fair value note
A6: GBP SSN (GBP 100.0m at 10.375pct) | B6: 100 | C6: 0 | D6: =B6+C6 -> 100 | E6: 10.375pct | F6: 47178 | G6: [H1] fair value note
A7: SSTL (GBP 450m) | B7: 0 | C7: 450 | D7: =B7+C7 -> 450 | E7: SONIA+6.75 | F7: 48030 | G7: [H1] going concern
A8: DDTL (GBP 100m delayed draw) | B8: 0 | C8: =Assumptions!$B$34*100 -> 0 | D8: =B8+C8 -> 0 | E8: SONIA+6.75 | F8: 48030 | G8: [H1] memo, excl. liquidity
A9: Super senior RCF (drawn) | B9: 163 | C9: -163 | D9: =B9+C9 -> 0 | E9: SONIA-based | F9: cancelled | G9: [H1] GBP 163.0m drawn
A10: YTC committed facility (drawn) | B10: 20 | C10: -20 | D10: =B10+C10 -> 0 | E10: n/d | F10: cancelled | G10: [H1] GBP 20m of GBP 50m
A11: Other bank loans and overdrafts | B11: 6.5 | C11: 0 | D11: =B11+C11 -> 6.5 | E11: n/d | F11: various | G11: [H1] balance to GBP 168.8m
A12: Inventory financing | B12: 39.1 | C12: 0 | D12: =B12+C12 -> 39.1 | E12: n/d | F12: 46296 | G12: [H1]
A13: Lease liabilities (IFRS 16) | B13: 89.7 | C13: 0 | D13: =B13+C13 -> 89.7 | E13: n/a | F13: various | G13: [H1]
A14: Gross debt (nominal) | B14: =SUM(B4:B13) -> 1675.6 | C14: =SUM(C4:C13) -> 267 | D14: =SUM(D4:D13) -> 1942.6
A15: Unamortised transaction fees | B15: -14.5 | G15: [H1] notes 12.1 + RCF 0.7 + YTC 1.7
A16: Gross debt (book) | B16: =B14+B15 -> 1661.1
A17: CHECK - reported gross debt [H1] | B17: 1661.1
A18: Difference | B18: =B16-B17 -> 0 | C18: =IF(ABS(B18)<0.05,"TIES","CHECK") -> TIES
A20: Cash | B20: 114.9 | C20: =450+Assumptions!$B$34*100-163-20-Assumptions!$B$33 -> 227 | D20: =B20+C20 -> 341.9
A21: Cash not available for short-term use | B21: 1.5 | D21: =B21 -> 1.5
A22: Net debt (nominal basis) | B22: =B14-B20-B21 -> 1559.2 | D22: =D14-D20-D21 -> 1599.2
A23: Available facilities | B23: 30.3 | D23: 0 | G23: RCF and YTC both cancelled [H1]
A24: TOTAL LIQUIDITY | B24: =B20+B23 -> 145.2 | D24: =D20+D23 -> 341.9
A25: CHECK vs disclosed | B25: 145.2 | D25: 340
A26: Difference | B26: =B24-B25 -> 0 | D26: =D24-D25 -> 1.9
A27: MEMO - undrawn DDTL capacity (NOT in liquidity) | D27: =(1-Assumptions!$B$34)*100 -> 100
A28: NOTE: the 'CHECK vs disclosed' above is calibrated to the BASE case (DDTL undrawn), which is how AML disclosed it.
A29: In the DOWNSIDE the DDTL is drawn, so post-transaction cash is c.GBP 100m higher by construction - the check will not tie there.
A30: CASH INTEREST SCHEDULE (GBP m)
A31: Line | B31: FY2026E | C31: FY2027E | D31: FY2028E | E31: FY2029E | F31: FY2030E | G31: FY2031E
A32: 2029 notes outstanding - year fraction | B32: 1 | C32: 1 | D32: 1 | E32: 0.25 | F32: 0 | G32: 0 | H32: Mature Mar-2029 [H1], so 3/12 of FY2029
A33: SSTL - year fraction | B33: 0.44 | C33: 1 | D33: 1 | E33: 1 | F33: 1 | G33: 1 | H33: Drawn 22-Jul-2026, so c.5.3 months of FY2026
A34: USD SSN interest | B34: =1050*0.1/Assumptions!C27*B32 -> 79.227345 | C34: =1050*0.1/Assumptions!D27*C32 -> 79.227345 | D34: =1050*0.1/Assumptions!E27*D32 -> 79.227345 | E34: =1050*0.1/Assumptions!F27*E32 -> 19.806836 | F34: =1050*0.1/Assumptions!G27*F32 -> 0 | G34: =1050*0.1/Assumptions!H27*G32 -> 0
A35: GBP SSN interest | B35: =565*0.10375*B32 -> 58.61875 | C35: =565*0.10375*C32 -> 58.61875 | D35: =565*0.10375*D32 -> 58.61875 | E35: =565*0.10375*E32 -> 14.654687 | F35: =565*0.10375*F32 -> 0 | G35: =565*0.10375*G32 -> 0
A36: SSTL interest | B36: =450*(Assumptions!C26+Assumptions!C28)*B33 -> 20.7306 | C36: =450*(Assumptions!D26+Assumptions!D28)*C33 -> 47.115 | D36: =450*(Assumptions!E26+Assumptions!E28)*D33 -> 47.115 | E36: =450*(Assumptions!F26+Assumptions!F28)*E33 -> 47.115 | F36: =450*(Assumptions!G26+Assumptions!G28)*F33 -> 47.115 | G36: =450*(Assumptions!H26+Assumptions!H28)*G33 -> 47.115
A37: DDTL interest | B37: =Assumptions!$B$34*100*(Assumptions!C26+Assumptions!C28)*B33 -> 0 | C37: =Assumptions!$B$34*100*(Assumptions!D26+Assumptions!D28)*C33 -> 0 | D37: =Assumptions!$B$34*100*(Assumptions!E26+Assumptions!E28)*D33 -> 0 | E37: =Assumptions!$B$34*100*(Assumptions!F26+Assumptions!F28)*E33 -> 0 | F37: =Assumptions!$B$34*100*(Assumptions!G26+Assumptions!G28)*F33 -> 0 | G37: =Assumptions!$B$34*100*(Assumptions!H26+Assumptions!H28)*G33 -> 0
A38: Refinancing debt interest (post Mar-29) | B38: =Assumptions!$B$35*1357.3*Assumptions!C29*(1-B32) -> 0 | C38: =Assumptions!$B$35*1357.3*Assumptions!D29*(1-C32) -> 0 | D38: =Assumptions!$B$35*1357.3*Assumptions!E29*(1-D32) -> 0 | E38: =Assumptions!$B$35*1357.3*Assumptions!F29*(1-E32) -> 205.22376 | F38: =Assumptions!$B$35*1357.3*Assumptions!G29*(1-F32) -> 273.63168 | G38: =Assumptions!$B$35*1357.3*Assumptions!H29*(1-G32) -> 273.63168 | H38: At 20.16pct = market-implied DISTRESS yield, NOT a forecast new-issue coupon. Never quote without this caveat. See YTM tab.
A39: Other interest (RCF/YTC/inventory/leases) | B39: 15 | C39: 8 | D39: 8 | E39: 8 | F39: 8 | G39: 8 | H39: FY26 includes part-year RCF/YTC. PROVISIONAL.
A40: Interest received | B40: 2 | C40: 2 | D40: 2 | E40: 2 | F40: 2 | G40: 2
A41: Subtotal - accrual basis | B41: =SUM(B34:B39)-B40 -> 171.57669 | C41: =SUM(C34:C39)-C40 -> 190.96109 | D41: =SUM(D34:D39)-D40 -> 190.96109 | E41: =SUM(E34:E39)-E40 -> 292.80028 | F41: =SUM(F34:F39)-F40 -> 326.74668 | G41: =SUM(G34:G39)-G40 -> 326.74668
A42: FY2026 calibration to guided cash interest | B42: =B44-B41 -> -11.576695 | C42: 0 | D42: 0 | E42: 0 | F42: 0 | G42: 0 | H42: FY2026 ONLY - calibrates to company guidance. NOT a silent override.
...

Sheet Model
A1: OPERATING MODEL, FREE CASH FLOW AND LIQUIDITY ROLL-FORWARD (GBP m)
A2: =Assumptions!C3 -> BASE CASE
B3: FY2025A | C3: FY2026E | D3: FY2027E | E3: FY2028E | F3: FY2029E | G3: FY2030E | H3: FY2031E
A5: OPERATING
A6: Total wholesale volumes | B6: =Assumptions!B13 -> 5448 | C6: =Assumptions!C13 -> 5900 | D6: =Assumptions!D13 -> 6100 | E6: =Assumptions!E13 -> 6300 | F6: =Assumptions!F13 -> 6400 | G6: =Assumptions!G13 -> 6500 | H6: =Assumptions!H13 -> 6600
A7: Blended ASP (GBP k) | B7: =Assumptions!B14 -> 230.9 | C7: =Assumptions!C14 -> 271 | D7: =Assumptions!D14 -> 274 | E7: =Assumptions!E14 -> 277 | F7: =Assumptions!F14 -> 280 | G7: =Assumptions!G14 -> 283 | H7: =Assumptions!H14 -> 286
A8: Revenue | B8: =B6*B7/1000 -> 1257.9432 | C8: =C6*C7/1000 -> 1598.9 | D8: =D6*D7/1000 -> 1671.4 | E8: =E6*E7/1000 -> 1745.1 | F8: =F6*F7/1000 -> 1792 | G8: =G6*G7/1000 -> 1839.5 | H8: =H6*H7/1000 -> 1887.6
A9: Gross margin pct | B9: =Assumptions!B15 -> 0.294 | C9: =Assumptions!C15 -> 0.35 | D9: =Assumptions!D15 -> 0.355 | E9: =Assumptions!E15 -> 0.355 | F9: =Assumptions!F15 -> 0.355 | G9: =Assumptions!G15 -> 0.355 | H9: =Assumptions!H15 -> 0.355
A10: Gross profit | B10: =B8*B9 -> 369.8353 | C10: =C8*C9 -> 559.615 | D10: =D8*D9 -> 593.347 | E10: =E8*E9 -> 619.5105 | F10: =F8*F9 -> 636.16 | G10: =G8*G9 -> 653.0225 | H10: =H8*H9 -> 670.098
A11: Adjusted opex (ex D and A) | B11: =-Assumptions!B16 -> -262 | C11: =-Assumptions!C16 -> -295 | D11: =-Assumptions!D16 -> -305 | E11: =-Assumptions!E16 -> -320 | F11: =-Assumptions!F16 -> -330 | G11: =-Assumptions!G16 -> -340 | H11: =-Assumptions!H16 -> -350
A12: Adjusted EBITDA | B12: =B10+B11 -> 107.8353 | C12: =C10+C11 -> 264.615 | D12: =D10+D11 -> 288.347 | E12: =E10+E11 -> 299.5105 | F12: =F10+F11 -> 306.16 | G12: =G10+G11 -> 313.0225 | H12: =H10+H11 -> 320.098
A13: Adjusted EBITDA margin | B13: =B12/B8 -> 0.085723505 | C13: =C12/C8 -> 0.16549815 | D13: =D12/D8 -> 0.17251825 | E13: =E12/E8 -> 0.17162942 | F13: =F12/F8 -> 0.17084821 | G13: =G12/G8 -> 0.17016716 | H13: =H12/H8 -> 0.16957936
A14: Adjusted D and A | B14: =-Assumptions!B17 -> -297 | C14: =-Assumptions!C17 -> -387.5 | D14: =-Assumptions!D17 -> -390 | E14: =-Assumptions!E17 -> -380 | F14: =-Assumptions!F17 -> -370 | G14: =-Assumptions!G17 -> -360 | H14: =-Assumptions!H17 -> -350
A15: Adjusted EBIT | B15: =B12+B14 -> -189.1647 | C15: =C12+C14 -> -122.885 | D15: =D12+D14 -> -101.653 | E15: =E12+E14 -> -80.4895 | F15: =F12+F14 -> -63.84 | G15: =G12+G14 -> -46.9775 | H15: =H12+H14 -> -29.902
A16: Adjusted EBIT margin | B16: =B15/B8 -> -0.15037618 | C16: =C15/C8 -> -0.076855963 | D16: =D15/D8 -> -0.060819074 | E16: =E15/E8 -> -0.046123145 | F16: =F15/F8 -> -0.035625 | G16: =G15/G8 -> -0.02553819 | H16: =H15/H8 -> -0.01584128
A18: FREE CASH FLOW
A19: Adjusted EBITDA | B19: =B12 -> 107.8353 | C19: =C12 -> 264.615 | D19: =D12 -> 288.347 | E19: =E12 -> 299.5105 | F19: =F12 -> 306.16 | G19: =G12 -> 313.0225 | H19: =H12 -> 320.098
A20: Working capital movement | B20: =Assumptions!B19 -> 0 | C20: =Assumptions!C19 -> -20 | D20: =Assumptions!D19 -> -10 | E20: =Assumptions!E19 -> -10 | F20: =Assumptions!F19 -> -10 | G20: =Assumptions!G19 -> -10 | H20: =Assumptions!H19 -> -10
A21: Lease payments | B21: =Assumptions!B20 -> 0 | C21: =Assumptions!C20 -> -10 | D21: =Assumptions!D20 -> -10 | E21: =Assumptions!E20 -> -10 | F21: =Assumptions!F20 -> -10 | G21: =Assumptions!G20 -> -10 | H21: =Assumptions!H20 -> -10
A22: Cash tax | B22: =Assumptions!B21 -> 0 | C22: =Assumptions!C21 -> -5 | D22: =Assumptions!D21 -> -5 | E22: =Assumptions!E21 -> -5 | F22: =Assumptions!F21 -> -5 | G22: =Assumptions!G21 -> -5 | H22: =Assumptions!H21 -> -5
A23: Other cash items | B23: =Assumptions!B22 -> 0 | C23: =Assumptions!C22 -> 0 | D23: =Assumptions!D22 -> 0 | E23: =Assumptions!E22 -> 0 | F23: =Assumptions!F22 -> 0 | G23: =Assumptions!G22 -> 0 | H23: =Assumptions!H22 -> 0
A24: Net cash interest paid | B24: -105 | C24: =-Debt!B43 -> -160 | D24: =-Debt!C43 -> -190.96109 | E24: =-Debt!D43 -> -190.96109 | F24: =-Debt!E43 -> -292.80028 | G24: =-Debt!F43 -> -326.74668 | H24: =-Debt!G43 -> -326.74668
A25: Capex | B25: =-Assumptions!B18 -> -341 | C25: =-Assumptions!C18 -> -300 | D25: =-Assumptions!D18 -> -350 | E25: =-Assumptions!E18 -> -350 | F25: =-Assumptions!F18 -> -350 | G25: =-Assumptions!G18 -> -350 | H25: =-Assumptions!H18 -> -300
A26: FREE CASH FLOW | B26: -410 | C26: =SUM(C19:C25) -> -230.385 | D26: =SUM(D19:D25) -> -277.61409 | E26: =SUM(E19:E25) -> -266.45059 | F26: =SUM(F19:F25) -> -361.64028 | G26: =SUM(G19:G25) -> -388.72418 | H26: =SUM(H19:H25) -> -331.64868
A27: FY2025A free cash outflow is the reported figure [AR25], not a build. FY25 cash interest is PROVISIONAL.
A29: NET DEBT AND LIQUIDITY
A30: Opening cash | B30: 249.9 | C30: 249.9 | D30: =C36 -> 307.315 | E30: =D36 -> 29.700905 | F30: =E36 -> -236.74969 | G30: =F36 -> -598.38997 | H30: =G36 -> -987.11415
A31: Free cash flow | C31: =C26 -> -230.385 | D31: =D26 -> -277.61409 | E31: =E26 -> -266.45059 | F31: =F26 -> -361.64028 | G31: =G26 -> -388.72418 | H31: =H26 -> -331.64868
A32: Net transaction proceeds | C32: =450+Assumptions!$B$34*100-163-20-Assumptions!$B$33 -> 227 | D32: 0 | E32: 0 | F32: 0 | G32: 0 | H32: 0
A33: Other financing / debt movements | C33: 60.8 | D33: 0 | E33: 0 | F33: 0 | G33: 0 | H33: 0
A34: 2029 notes repayment | C34: 0 | D34: 0 | E34: 0 | F34: -1357.3 | G34: 0 | H34: 0
A35: 2029 refinancing proceeds | C35: 0 | D35: 0 | E35: 0 | F35: =Assumptions!$B$35*1357.3 -> 1357.3 | G35: 0 | H35: 0
A36: Closing cash (before further funding) | B36: 249.9 | C36: =SUM(C30:C35) -> 307.315 | D36: =SUM(D30:D35) -> 29.700905 | E36: =SUM(E30:E35) -> -236.74969 | F36: =SUM(F30:F35) -> -598.38997 | G36: =SUM(G30:G35) -> -987.11415 | H36: =SUM(H30:H35) -> -1318.7628
A37: Available facilities | C37: 0 | D37: 0 | E37: 0 | F37: 0 | G37: 0 | H37: 0
A38: TOTAL LIQUIDITY (before further funding) | B38: 250 | C38: =C36+C37 -> 307.315 | D38: =D36+D37 -> 29.700905 | E38: =E36+E37 -> -236.74969 | F38: =F36+F37 -> -598.38997 | G38: =G36+G37 -> -987.11415 | H38: =H36+H37 -> -1318.7628
A39: Memo: undrawn DDTL (not in liquidity) | C39: =(1-Assumptions!$B$34)*100 -> 100 | D39: =(1-Assumptions!$B$34)*100 -> 100 | E39: =(1-Assumptions!$B$34)*100 -> 100 | F39: =(1-Assumptions!$B$34)*100 -> 100 | G39: =(1-Assumptions!$B$34)*100 -> 100 | H39: =(1-Assumptions!$B$34)*100 -> 100
A40: Gross debt (nominal) | C40: =Debt!$D$14 -> 1942.6 | D40: =C40+D34+D35 -> 1942.6 | E40: =D40+E34+E35 -> 1942.6 | F40: =E40+F34+F35 -> 1942.6 | G40: =F40+G34+G35 -> 1942.6 | H40: =G40+H34+H35 -> 1942.6
A41: Net debt | C41: =C40-C36-1.5 -> 1633.785 | D41: =D40-D36-1.5 -> 1911.3991 | E41: =E40-E36-1.5 -> 2177.8497 | F41: =F40-F36-1.5 -> 2539.49 | G41: =G40-G36-1.5 -> 2928.2142 | H41: =H40-H36-1.5 -> 3259.8628
A42: Net debt / adjusted EBITDA | C42: =IF(C12>0,C41/C12,"n.m.") -> 6.1741965 | D42: =IF(D12>0,D41/D12,"n.m.") -> 6.6288156 | E42: =IF(E12>0,E41/E12,"n.m.") -> 7.2713634 | F42: =IF(F12>0,F41/F12,"n.m.") -> 8.2946498 | G42: =IF(G12>0,G41/G12,"n.m.") -> 9.3546443 | H42: =IF(H12>0,H41/H12,"n.m.") -> 10.183953
A43: Adjusted EBITDA / net cash interest | C43: =IF(-C24>0,C12/-C24,"n.m.") -> 1.6538438 | D43: =IF(-D24>0,D12/-D24,"n.m.") -> 1.5099777 | E43: =IF(-E24>0,E12/-E24,"n.m.") -> 1.5684373 | F43: =IF(-F24>0,F12/-F24,"n.m.") -> 1.0456274 | G43: =IF(-G24>0,G12/-G24,"n.m.") -> 0.95799749 | H43: =IF(-H24>0,H12/-H24,"n.m.") -> 0.97965188
...

Sheet Outputs
A1: CREDIT METRICS DASHBOARD
A2: =Assumptions!C3 -> BASE CASE
A3: PROVISIONAL - FY2027-31 drivers are unsourced judgement awaiting sign-off.
A4: CAVEAT TRAVELS WITH THE NUMBER: the 20.16pct refi rate is a market-implied DISTRESS yield (embeds default probability), NOT a forecast new-issue coupon. Carry this into the memo and deck.
B5: FY2025A | C5: FY2026E | D5: FY2027E | E5: FY2028E | F5: FY2029E | G5: FY2030E | H5: FY2031E
A6: Revenue | B6: =Model!B8 -> 1257.9432 | C6: =Model!C8 -> 1598.9 | D6: =Model!D8 -> 1671.4 | E6: =Model!E8 -> 1745.1 | F6: =Model!F8 -> 1792 | G6: =Model!G8 -> 1839.5 | H6: =Model!H8 -> 1887.6
A7: Adjusted EBITDA | B7: =Model!B12 -> 107.8353 | C7: =Model!C12 -> 264.615 | D7: =Model!D12 -> 288.347 | E7: =Model!E12 -> 299.5105 | F7: =Model!F12 -> 306.16 | G7: =Model!G12 -> 313.0225 | H7: =Model!H12 -> 320.098
A8: Adjusted EBIT | B8: =Model!B15 -> -189.1647 | C8: =Model!C15 -> -122.885 | D8: =Model!D15 -> -101.653 | E8: =Model!E15 -> -80.4895 | F8: =Model!F15 -> -63.84 | G8: =Model!G15 -> -46.9775 | H8: =Model!H15 -> -29.902
A9: Free cash flow | B9: =Model!B26 -> -410 | C9: =Model!C26 -> -230.385 | D9: =Model!D26 -> -277.61409 | E9: =Model!E26 -> -266.45059 | F9: =Model!F26 -> -361.64028 | G9: =Model!G26 -> -388.72418 | H9: =Model!H26 -> -331.64868
A10: Net cash interest | B10: =Model!B24 -> -105 | C10: =Model!C24 -> -160 | D10: =Model!D24 -> -190.96109 | E10: =Model!E24 -> -190.96109 | F10: =Model!F24 -> -292.80028 | G10: =Model!G24 -> -326.74668 | H10: =Model!H24 -> -326.74668
A11: Gross debt (nominal) | B11: =Model!B40 -> 0 | C11: =Model!C40 -> 1942.6 | D11: =Model!D40 -> 1942.6 | E11: =Model!E40 -> 1942.6 | F11: =Model!F40 -> 1942.6 | G11: =Model!G40 -> 1942.6 | H11: =Model!H40 -> 1942.6
A12: Net debt | B12: =Model!B41 -> 0 | C12: =Model!C41 -> 1633.785 | D12: =Model!D41 -> 1911.3991 | E12: =Model!E41 -> 2177.8497 | F12: =Model!F41 -> 2539.49 | G12: =Model!G41 -> 2928.2142 | H12: =Model!H41 -> 3259.8628
A13: Net debt / adj EBITDA | B13: =Model!B42 -> 0 | C13: =Model!C42 -> 6.1741965 | D13: =Model!D42 -> 6.6288156 | E13: =Model!E42 -> 7.2713634 | F13: =Model!F42 -> 8.2946498 | G13: =Model!G42 -> 9.3546443 | H13: =Model!H42 -> 10.183953
A14: Adj EBITDA / cash interest | B14: =Model!B43 -> 0 | C14: =Model!C43 -> 1.6538438 | D14: =Model!D43 -> 1.5099777 | E14: =Model!E43 -> 1.5684373 | F14: =Model!F43 -> 1.0456274 | G14: =Model!G43 -> 0.95799749 | H14: =Model!H43 -> 0.97965188
A15: Total liquidity | B15: =Model!B38 -> 250 | C15: =Model!C38 -> 307.315 | D15: =Model!D38 -> 29.700905 | E15: =Model!E38 -> -236.74969 | F15: =Model!F38 -> -598.38997 | G15: =Model!G38 -> -987.11415 | H15: =Model!H38 -> -1318.7628
A16: Liquidity headroom vs covenant | B16: =Model!B44 -> 0 | C16: =Model!C44 -> 207.315 | D16: =Model!D44 -> -70.299095 | E16: =Model!E44 -> -336.74969 | F16: =Model!F44 -> -698.38997 | G16: =Model!G44 -> -1087.1142 | H16: =Model!H44 -> -1418.7628
A17: Memo: undrawn DDTL | B17: =Model!B39 -> 0 | C17: =Model!C39 -> 100 | D17: =Model!D39 -> 100 | E17: =Model!E39 -> 100 | F17: =Model!F39 -> 100 | G17: =Model!G39 -> 100 | H17: =Model!H39 -> 100
A19: HEADLINE ANSWER
A20: First year liquidity falls below the covenant threshold | B20: =IFERROR(INDEX($C$5:$H$5,MATCH(TRUE,INDEX($C$16:$H$16<0,0),0)),"No breach through FY2031") -> FY2027E
A21: First year liquidity falls below zero | B21: =IFERROR(INDEX($C$5:$H$5,MATCH(TRUE,INDEX($C$15:$H$15<0,0),0)),"Positive through FY2031") -> FY2028E
A22: 2029 refinancing requirement (GBP m) | B22: 1357.3
A23: FY2027 cash interest step-up vs FY2026 (increase in cost) | B23: =-(Model!D24-Model!C24) -> 30.961095
A24: Cumulative FCF FY2027-FY2031 | B24: =SUM(Model!D26:H26) -> -1626.0778
A25: Peak funding gap by FY2031 (GBP m) | B25: =MAX(Model!C45:H45) -> 1318.7628
A26: Pro forma liquidity at 30-Jun-26 (disclosed) | B26: =Debt!D24 -> 341.9
A27: Liquidity runway from 22-Jul-2026 (see Refinancing tab) | B27: BASE c.19 months (crosses zero c.Feb-2028) | DOWNSIDE c.16 months (crosses zero c.Nov-2027)
A28: COVENANT THRESHOLD SENSITIVITY - the breach date is a function of an UNSOURCED input
A29: Minimum liquidity threshold (GBP m) | B29: First breach year | C29: Headroom at FY2027 (GBP m)
A30: 75 | B30: =IFERROR(INDEX($C$5:$H$5,MATCH(TRUE,INDEX(Model!$C$38:$H$38<A30,0),0)),"No breach to FY2031") -> FY2027E | C30: =Model!D38-A30 -> -45.299095
A31: 100 | B31: =IFERROR(INDEX($C$5:$H$5,MATCH(TRUE,INDEX(Model!$C$38:$H$38<A31,0),0)),"No breach to FY2031") -> FY2027E | C31: =Model!D38-A31 -> -70.299095
A32: 125 | B32: =IFERROR(INDEX($C$5:$H$5,MATCH(TRUE,INDEX(Model!$C$38:$H$38<A32,0),0)),"No breach to FY2031") -> FY2027E | C32: =Model!D38-A32 -> -95.299095
A34: The SSTL minimum-liquidity covenant is disclosed [H1] but its LEVEL is not. The model uses Assumptions!B36.
A35: Across the plausible 75-125 range the breach year is unchanged, so the conclusion does not hinge on this input.
A36: This block reflects the ACTIVE scenario (Assumptions!B3).
A38: SCENARIO COMPARISON - static snapshot taken 2026-08-07, refresh if drivers change
A39: Metric | B39: BASE | C39: DOWNSIDE | D39: Delta
A40: FY2027 revenue (GBP m) | B40: 1671.4 | C40: 1357.8 | D40: -313.6 (-18.8pct)
A41: FY2027 adjusted EBITDA (GBP m) | B41: 288.3 | C41: 129.5 | D41: -158.8 (-55pct)
A42: FY2027 EBITDA margin | B42: 17.3pct | C42: 9.5pct | D42: -780bps
A43: FY2027 free cash flow (GBP m) | B43: -277.6 | C43: -455.4 | D43: -177.8
...

Sheet YTM
A1: IMPLIED YIELD TO MATURITY ON THE 2029 NOTES - basis for the refinancing rate
A2: Settlement 30-Jun-2026. Maturity 31-Mar-2029 (2.75 years). Semi-annual coupons, 6 payments remaining.
A3: Prices are the disclosed fair values at 30-Jun-2026 [H1 fair value note] - see SOURCES.md section 3.
A5: Tranche | B5: Nominal | C5: Fair value | D5: Clean price pct | E5: Coupon pct | F5: Accrued pct | G5: Dirty price pct | H5: Implied YTM pct
A6: USD SSN 10.000pct | B6: 792.3 | C6: 629.9 | D6: =100*C6/B6 -> 79.502714 | E6: 10 | F6: =E6*0.25 -> 2.5 | G6: =D6+F6 -> 82.002714 | H6: 20.02
A7: GBP SSN 10.375pct (465m) | B7: 465 | C7: 372.3 | D7: =100*C7/B7 -> 80.064516 | E7: 10.375 | F7: =E7*0.25 -> 2.59375 | G7: =D7+F7 -> 82.658266 | H7: 20.14
A8: GBP SSN 10.375pct (100m) | B8: 100 | C8: 77.8 | D8: =100*C8/B8 -> 77.8 | E8: 10.375 | F8: =E8*0.25 -> 2.59375 | G8: =D8+F8 -> 80.39375 | H8: 21.44
A9: BLENDED | B9: 1357.3 | C9: 1080 | D9: =100*C9/B9 -> 79.569734 | E9: 10.156 | F9: =E9*0.25 -> 2.539 | G9: =D9+F9 -> 82.108734 | H9: 20.16
A11: Method
A12: Dirty price = clean price + accrued interest (3 months since the 31-Mar coupon).
A13: Solve for y such that: sum over t of (coupon/2)/(1+y/2)^(2t) + 100/(1+y/2)^(2*2.75) = dirty price,
A14: with t = 0.25, 0.75, 1.25, 1.75, 2.25, 2.75 years. Solved by bisection to 1e-6.
A15: Blended coupon = (792.3 x 10.000 + 565.0 x 10.375) / 1357.3 = 10.156 pct.
A17: RESULT: blended implied YTM = 20.16 pct. This is the refinancing rate used on the Assumptions tab.
A19: INTERPRETIVE CAVEAT - read before quoting this number:
A20: 20.16 pct is a DISTRESS yield. It embeds the market's probability of default, not a clean forecast of a new-issue coupon.
A21: Using it as the 2029 refinancing rate is deliberately conservative: it prices the refinancing at what the market thinks
A22: this risk costs TODAY. If AML reaches 2029 in a position to refinance at all, the credit would likely have improved and
A23: the true coupon would be lower. The honest reading is not 'AML will pay 20 pct' but 'the market does not currently believe
A24: these notes can be refinanced on economic terms' - which is itself the finding.

Sheet Attribution
A1: WHAT DRIVES THE LEVERAGE AND COVERAGE REVERSAL - stepwise attribution
A2: Cumulative walk from the pre-review base case to the current one. Each step adds one change.
A3: Produced by re-running this workbook with each input reverted; S4 reconciles exactly to the live model.
A5: Step | B5: FY29 interest | C5: FY31 interest | D5: FY29 leverage | E5: FY31 leverage | F5: FY29 coverage | G5: FY31 coverage | H5: Peak funding gap
A6: S0 Pre-review base case | B6: 200.8 | C6: 203.7 | D6: 5.71 | E6: 5.56 | F6: 1.99 | G6: 2.21 | H6: 560
A7: S1 + margin cap to 17.1pct | B7: 200.8 | C7: 203.7 | D7: 8.04 | E7: 9.17 | F7: 1.52 | G7: 1.57 | H7: 995.3
A8: S2 + SONIA 4.00 to 3.72pct | B8: 199.6 | C8: 202.4 | D8: 8.03 | E8: 9.15 | F8: 1.53 | G8: 1.58 | H8: 988.4
A9: S3 + FY2026 interest calibration | B9: 199.6 | C9: 202.4 | D9: 7.99 | E9: 9.12 | F9: 1.53 | G9: 1.58 | H9: 976.9
A10: S4 + refi 11.0 to 20.16pct (CURRENT) | B10: 292.8 | C10: 326.7 | D10: 8.29 | E10: 10.18 | F10: 1.05 | G10: 0.98 | H10: 1318.8
A12: CONTRIBUTION TO THE TOTAL SWING
A13: Metric | B13: Total swing | C13: Margin cap | D13: SONIA | E13: FY26 calib. | F13: Refi rate
A14: FY2031 leverage | B14: +4.62x | C14: +3.61x (78pct) | D14: -0.02x (0pct) | E14: -0.03x (-1pct) | F14: +1.06x (23pct)
A15: FY2029 coverage | B15: -0.94x | C15: -0.47x (50pct) | D15: +0.01x (-1pct) | E15: 0.00x (0pct) | F15: -0.48x (51pct)
A16: FY2031 coverage | B16: -1.23x | C16: -0.64x (52pct) | D16: +0.01x (-1pct) | E16: 0.00x (0pct) | F16: -0.60x (49pct)
A17: Peak funding gap (GBP m) | B17: 758.8 | C17: +435.3 (57pct) | D17: -6.9 (-1pct) | E17: -11.5 (-2pct) | F17: +341.9 (45pct)
A19: CONCLUSION
A20: The leverage reversal is driven MAINLY by the margin cap (78pct of the FY2031 swing), not the refi rate (23pct).
A21: The coverage collapse is roughly an even split between the two (c.50/50).
A22: SONIA and the FY2026 calibration are immaterial (under 2pct each) and both slightly REDUCE stress.
A24: This is NOT a compounding of unexamined provisional assumptions. Two deliberate corrections did the work, and both
A25: replaced a weaker input with a better-grounded one: the margin cap is anchored to AML's own FY2024 high (sourced),
A26: and the refi rate is computed from the disclosed market price (sourced) rather than guessed.
A28: ROBUSTNESS: step S1 shows that with the margin cap alone - refi still at 11pct - leverage already rises to 9.17x and
A29: the funding gap reaches GBP 995m. The conclusion does NOT depend on the distress yield.

Sheet Refinancing
A1: 2029 REFINANCING FEASIBILITY AND THE SELF-SUSTAINING TEST
A2: Answers two of the brief's core questions: can AML refinance the 2029 notes, and when does it become self-sustaining?
A3: All figures BASE CASE. GBP 1,357.3m of senior secured notes mature March 2029.
A5: A. WHAT WOULD REFINANCING COST? (FY2030, first full year post-refinancing)
A6: Refinancing rate | B6: FY30 cash interest | C6: FY30 coverage | D6: FY30 free cash flow | E6: Peak funding gap | F6: Comment
A7: 0.00pct (hypothetical) | B7: 53.1 | C7: 5.89 | D7: -115.1 | E7: 566.3 | F7: Even at ZERO cost of debt, free cash flow stays negative
A8: 7.50pct | B8: 154.9 | C8: 2.02 | D8: -216.9 | E8: 846.2 | F8: Coverage reaches 2.0x only here - well inside investment-grade pricing
A9: 10.375pct (existing coupon) | B9: 193.9 | C9: 1.61 | D9: -255.9 | E9: 953.5 | F9: Refinancing at the CURRENT coupon still leaves 1.6x and negative FCF
A10: 12.50pct | B10: 222.8 | C10: 1.41 | D10: -284.8 | E10: 1032.8
A11: 15.00pct | B11: 256.7 | C11: 1.22 | D11: -318.7 | E11: 1126.2
A12: 20.16pct (market-implied) | B12: 326.7 | C12: 0.96 | D12: -388.7 | E12: 1318.8 | F12: DISTRESS yield, not a forecast coupon - see YTM tab. Coverage below 1.0x
A14: THE DECISIVE RESULT
A15: At a 0pct refinancing cost - an impossible best case - FY2030 free cash flow is still MINUS GBP 115m.
A16: Refinancing terms are therefore not the binding constraint. No achievable coupon makes this capital structure work.
A17: Refinancing feasibility is a question about the BUSINESS, not about credit markets.
A19: B. SELF-SUSTAINING TEST - can the business fund its own capex, before any interest?
A20: Base case (GBP m) | B20: FY2026E | C20: FY2027E | D20: FY2028E | E20: FY2029E | F20: FY2030E | G20: FY2031E
A21: Adjusted EBITDA | B21: 264.6 | C21: 288.3 | D21: 299.5 | E21: 306.2 | F21: 313 | G21: 320.1
A22: Capex | B22: -300 | C22: -350 | D22: -350 | E22: -350 | F22: -350 | G22: -300
A23: EBITDA less capex | B23: -35.4 | C23: -61.7 | D23: -50.5 | E23: -43.8 | F23: -37 | G23: 20.1
A24: Cash interest | B24: -160 | C24: -191 | D24: -191 | E24: -292.8 | F24: -326.7 | G24: -326.7
A25: Free cash flow | B25: -230.4 | C25: -277.6 | D25: -266.5 | E25: -361.6 | F25: -388.7 | G25: -331.6
A27: EBITDA does not cover CAPEX ALONE until FY2031 - and then by only GBP 20m, before a penny of interest.
A28: On these drivers Aston Martin does NOT become self-sustaining within the forecast horizon.
A30: C. WHAT WOULD HAVE TO BE TRUE for FY2031 free cash flow to reach zero?
A31: Required EBITDA | B31: GBP 651.7m | C31: vs GBP 320.1m modelled - more than DOUBLE
A32: Implied revenue (at 35.5pct GM, opex GBP 350m) | B32: GBP 2,823m | C32: vs GBP 1,888m modelled - c.+50pct
A33: Implied wholesale volumes (at ASP GBP 286k) | B33: c.9,870 units | C33: vs 6,600 modelled, and vs 5,448 actual in FY2025
A34: Alternative: refinance at existing 10.375pct | B34: still needs EBITDA of c.GBP 519m | C34: c.+62pct vs modelled
A36: For context, FY2025 actual wholesale volumes were 5,448 and peak historic adjusted EBITDA was GBP 271m (FY2024).
A38: D. LIQUIDITY RUNWAY from the 22-Jul-2026 financing
A39: Scenario | B39: Crosses zero | C39: Runway | D39: Basis
A40: BASE | B40: c. Feb-2028 | C40: c. 19 months | D40: FY2028 opening liquidity GBP 29.7m against FY2028 free cash outflow of GBP 266.5m (11.1pct through the year)
A41: DOWNSIDE | B41: c. Nov-2027 | C41: c. 16 months | D41: FY2027 opening liquidity GBP 407.3m (incl. drawn DDTL) against FY2027 free cash outflow of GBP 455.4m (89.4pct through)
A43: Straight-line interpolation within the year - the model is annual, so treat these as indicative quarters, not dates.
A45: E. ANSWERS TO THE BRIEF'S QUESTIONS
A46: Can AML afford the additional interest? | B46: No. FY2027 cash interest of GBP 191m against EBITDA of GBP 288m leaves 1.5x coverage, and free cash flow stays negative throughout.
A47: Can it refinance the 2029 notes? | B47: Not on terms that help. Even at a 0pct coupon FY2030 free cash flow is minus GBP 115m. The constraint is the business, not the market.
A48: Is further funding required before 2031? | B48: Yes. Base case peak funding gap GBP 1,319m; downside GBP 2,163m. Required from FY2028 (base) or FY2027 (downside).
A49: When does it become self-sustaining? | B49: Not within the horizon. EBITDA does not cover capex alone until FY2031, and never covers capex plus interest.
...

Sheet Reconciliation
A1: WHY THE MODEL EXHAUSTS LIQUIDITY AT A MILDER SHOCK THAN MANAGEMENT'S REVERSE STRESS TEST
A2: THE CHALLENGE: our downside uses -23pct total volumes (management's -25pct CORE) yet fully exhausts liquidity.
A3: Management's disclosure implies -55pct core is needed to exhaust liquidity - roughly double our stress. Why?
A5: TEST 1 - LEVER WALK: which stress lever actually causes exhaustion?
A6: Variant (all vs FY2027 year-end liquidity) | B6: FY27 EBITDA | C6: FY27 liquidity | D6: Change | E6: Liquidity exhausted
A7: BASE (no stress) | B7: 288.3 | C7: 29.7 | D7: - | E7: FY2028
A8: V1 core volumes -25pct ONLY | B8: 176.8 | C8: -81.8 | D8: -111.5 | E8: FY2027
A9: V2 + gross margin 32pct | B9: 129.3 | C9: -129.3 | D9: -47.5 | E9: FY2027
A10: V3 + SONIA 5.25pct | B10: 129.3 | C10: -136.2 | D10: -6.9 | E10: FY2027
A11: V4 + DDTL drawn (= DOWNSIDE) | B11: 129.3 | C11: -48.2 | D11: 88 | E11: FY2027
A13: FINDING: the margin assumption is NOT the cause. A volume-only -25pct stress already exhausts liquidity
A14: in FY2027 (-GBP 81.8m). The margin cut adds a further -GBP 47.5m but is not required for exhaustion.
A15: SONIA is trivial (-GBP 6.9m). Drawing the DDTL ADDS GBP 88.0m net of its own interest.
A17: TEST 2 - VOLUME-ONLY LADDER: what shock does our model actually need?
A18: Core volume cut (margin and SONIA at base, DDTL undrawn) | B18: FY27 revenue | C18: FY27 EBITDA | D18: FY27 liquidity | E18: Liquidity exhausted
A19: 0pct (base) | B19: 1671.4 | C19: 288.3 | D19: 29.7 | E19: FY2028
A20: -5pct | B20: 1608.6 | C20: 266 | D20: 7.4 | E20: FY2028
A21: -6.6pct | B21: 1588.4 | C21: 258.9 | D21: 0.3 | E21: FY2028 <- BREAKEVEN
A22: -10pct | B22: 1545.7 | C22: 243.7 | D22: -14.9 | E22: FY2027
A23: -25pct (mgmt covenant marker) | B23: 1357.2 | C23: 176.8 | D23: -81.8 | E23: FY2027
A24: -40pct | B24: 1168.6 | C24: 109.9 | D24: -148.8 | E24: FY2027
A25: -55pct (mgmt liquidity marker) | B25: 980.1 | C25: 42.9 | D25: -215.7 | E25: FY2027
A27: FINDING: our model tips into FY2027 exhaustion at only -6.6pct core volumes - versus management's -55pct.
A28: The gap is therefore NOT in the stress levers. It is in the BASE CASE we are stressing from.
A30: WHY: the base case is already on the cliff edge
A31: Base FY2027 committed outflow vs earnings (GBP m)
A32: Adjusted EBITDA | B32: 288.3
A33: Cash interest | B33: -191
A34: Capex | B34: -350
A35: Working capital, leases, tax | B35: -25
A36: FREE CASH FLOW | B36: -277.6
A38: Interest (GBP 191m) plus capex (GBP 350m) = GBP 541m of largely committed outflow against GBP 288m of EBITDA.
A39: Base FY2027 year-end liquidity is only GBP 29.7m. Any material stress tips it negative - hence -6.6pct.
A41: TEST 3 - is this an artefact of OUR capex phasing? No.
A42: Capex phasing FY2026-30 (total held at c.GBP 1.7bn, which IS sourced guidance) | B42: FY27 liquidity | C42: FY28 liquidity | D42: Liquidity exhausted
A43: A 300/350/350/350/350 (current) | B43: 29.7 | C43: -236.7 | D43: FY2028
A44: B 300/300/350/375/375 | B44: 79.7 | C44: -186.7 | D44: FY2028
A45: C 300/250/350/400/400 | B45: 129.7 | C45: -136.7 | D45: FY2028
A47: Phasing moves FY2027 liquidity by up to GBP 100m but does NOT change the exhaustion year. The programme TOTAL
A48: is sourced guidance, so re-phasing only shifts the burn between years - it cannot avoid it.
...

Sheet Maturity
A1: DEBT MATURITY PROFILE (GBP m, nominal) - POST-TRANSACTION
A3: Instrument | B3: 2026 | C3: 2027 | D3: 2028 | E3: 2029 | F3: 2030 | G3: 2031
A4: USD SSN (Mar-29) | B4: 0 | C4: 0 | D4: 0 | E4: =Debt!D4 -> 792.3 | F4: 0 | G4: 0
A5: GBP SSN (Mar-29) | B5: 0 | C5: 0 | D5: 0 | E5: =Debt!D5+Debt!D6 -> 565 | F5: 0 | G5: 0
A6: SSTL (Jul-31) | B6: 0 | C6: 0 | D6: 0 | E6: 0 | F6: 0 | G6: =Debt!D7 -> 450
A7: DDTL (Jul-31) | B7: 0 | C7: 0 | D7: 0 | E7: 0 | F7: 0 | G7: =Debt!D8 -> 0
A8: Inventory financing | B8: =Debt!D12 -> 39.1 | C8: 0 | D8: 0 | E8: 0 | F8: 0 | G8: 0
A9: Other bank loans | B9: =Debt!D11 -> 6.5 | C9: 0 | D9: 0 | E9: 0 | F9: 0 | G9: 0
A10: TOTAL | B10: =SUM(B4:B9) -> 45.6 | C10: =SUM(C4:C9) -> 0 | D10: =SUM(D4:D9) -> 0 | E10: =SUM(E4:E9) -> 1357.3 | F10: =SUM(F4:F9) -> 0 | G10: =SUM(G4:G9) -> 450
A12: Lease liabilities (GBP 89.7m) amortise across the period and are excluded above.
A13: The Mar-2029 wall is GBP 1,357.3m nominal - c.4x the pro forma liquidity of c.GBP 340m.
